Using device: cuda
C:\Full_FR\Project\.venv\Lib\site-packages\PIL\Image.py:1047: UserWarning: Palette images with Transparency expressed in bytes should be converted to RGBA images
  warnings.warn(
Traceback (most recent call last):
  File "C:\Full_FR\Project\.venv\Lib\site-packages\pandas\core\indexes\range.py", line 413, in get_loc
    return self._range.index(new_key)
           ^^^^^^^^^^^^^^^^^^^^^^^^^^
ValueError: 13608 is not in range

The above exception was the direct cause of the following exception:

Traceback (most recent call last):
  File "C:\Full_FR\Project\models\src_informative\train.py", line 208, in <module>
    train(hyperparameters)
  File "C:\Full_FR\Project\models\src_informative\train.py", line 96, in train
    labels = [item['label'].item() for item in train_dataset]
             ^^^^^^^^^^^^^^^^^^^^^^^^^^^^^^^^^^^^^^^^^^^^^^^^
  File "C:\Full_FR\Project\models\src_informative\data_loader.py", line 24, in __getitem__
    text = self.annotations_df.loc[idx, 'text']
           ~~~~~~~~~~~~~~~~~~~~~~~^^^^^^^^^^^^^
  File "C:\Full_FR\Project\.venv\Lib\site-packages\pandas\core\indexing.py", line 1183, in __getitem__
    return self.obj._get_value(*key, takeable=self._takeable)
           ^^^^^^^^^^^^^^^^^^^^^^^^^^^^^^^^^^^^^^^^^^^^^^^^^^
  File "C:\Full_FR\Project\.venv\Lib\site-packages\pandas\core\frame.py", line 4226, in _get_value
    row = self.index.get_loc(index)
          ^^^^^^^^^^^^^^^^^^^^^^^^^
  File "C:\Full_FR\Project\.venv\Lib\site-packages\pandas\core\indexes\range.py", line 415, in get_loc
    raise KeyError(key) from err
KeyError: 13608
